Workbook

Sheet Table 1
A1: Table 1. Cetacean-specific primers for eDNA metabarcoding tested empirically
A2: Primer set ID | B2: Region | C2: Forward primer sequence | D2: Reverse primer sequence | E2: Forward primer length (bp) | F2: Reverse primer length (bp) | G2: Insert length (bp) | H2: GC% (forward) | I2: GC% (reverse)
A3: Mu31F/Dc320R (µCeta*) | B3: 12S rRNA | C3: GACACTGAAAATGTCTAGATGG | D3: TYAATCGTATGACCGCGGTG | E3: =LEN(C3) -> 22 | F3: =LEN(D3) -> 20 | G3: 268 | H3: 0.40909091 | I3: 0.525
A4: Dc671F/Dc1015R | B4: 12S rRNA | C4: GCTACTYCAGTCTATATACC | D4: CACACYTTCCRGTAYGCTTACC | E4: =LEN(C4) -> 20 | F4: =LEN(D4) -> 22 | G4: 325 | H4: 0.425 | I4: 0.52272727
A5: Mu2084F/Dc2438R | B5: 16S rRNA | C5: ATGAAYGGCCACACGAGGGTTTTA | D5: TGTCCTGATCCAACATCGAGG | E5: =LEN(C5) -> 24 | F5: =LEN(D5) -> 21 | G5: 331 | H5: 0.47916667 | I5: 0.52380952
A6: Mu9459F/Mu9822R | B6: NAD3 | C6: CTGACTTCCAATCAGTTRGTTTCGG | D6: CATTCTARRCCYTYTTGRG | E6: =LEN(C6) -> 25 | F6: =LEN(D6) -> 19 | G6: 339 | H6: 0.46 | I6: 0.44736842
A7: Bold characters indicate degenerated bases.
A8: *The primer set, Mu31F/Dc320R, is named µCeta-F/R.

Sheet Table 2
A1: Table 2. List of cetacean species for testing cetacean primers using tissue-extracted DNA
A2: Species | B2: Family | C2: Accession No. (if amplified)
C3: Mu31F + Dc320R | D3: Dc671F + Dc1015R | E3: Mu2084F + Dc2438R | F3: Mu9459F + Mu9822R
A4: Megaptera novaeangliae | B4: Balaenopteridae | C4: ✓ | D4: ✓ | E4: ✓ | F4: ✓
A5: Globicephala macrorhynchus | B5: Delphinidae | C5: ✓ | D5: No | E5: ✓ | F5: No
A6: Grampus griseus | B6: Delphinidae | C6: ✓ | D6: ✓ | E6: ✓ | F6: ✓
A7: Lagenodelphis hosei | B7: Delphinidae | C7: ✓ | D7: ✓ | E7: ✓ | F7: ✓
A8: Peponocephala electra | B8: Delphinidae | C8: ✓ | D8: ✓ | E8: ✓ | F8: ✓
A9: Pseudorca crassidens | B9: Delphinidae | C9: ✓ | D9: ✓ | E9: ✓ | F9: ✓
A10: Sousa chinensis | B10: Delphinidae | C10: ✓ | D10: ✓ | E10: ✓ | F10: ✓
A11: Stenella attenuata | B11: Delphinidae | C11: ✓ | D11: ✓ | E11: ✓ | F11: ✓
A12: Stenella coeruleoalba | B12: Delphinidae | C12: ✓ | D12: ✓ | E12: ✓ | F12: ✓
A13: Steno bredanensis | B13: Delphinidae | C13: ✓ | D13: ✓ | E13: ✓ | F13: ✓
A14: Tursiops aduncus | B14: Delphinidae | C14: ✓ | D14: ✓ | E14: ✓ | F14: ✓
A15: Tursiops truncatus | B15: Delphinidae | C15: ✓ | D15: ✓ | E15: ✓ | F15: ✓
... A22: Ziphius cavirostris | B22: Ziphiidae | C22: ✓ | D22: ✓ | E22: ✓ | F22: ✓

Sheet S1 Mammal list
A1: Table S1. List of mammal species for primer design
A2: Accession No. | B2: Genus_Species | C2: Order | D2: Suborder | E2: Family | F2: Genus | G2: Species
A3: Cetacea
A4: NC_005268.1 | B4: Balaena mysticetus | C4: Cetartiodactyla | D4: Mysticeti | E4: Balaenidae | F4: Balaena | G4: mysticetus
A5: NC_006930.1 | B5: Eubalaena australis | C5: Cetartiodactyla | D5: Mysticeti | E5: Balaenidae | F5: Eubalaena | G5: australis
A6: NC_037444.1 | B6: Eubalaena glacialis | C6: Cetartiodactyla | D6: Mysticeti | E6: Balaenidae | F6: Eubalaena | G6: glacialis
A7: NC_006931.1 | B7: Eubalaena japonica | C7: Cetartiodactyla | D7: Mysticeti | E7: Balaenidae | F7: Eubalaena | G7: japonica
A8: NC_005271.1 | B8: Balaenoptera acutorostrata | C8: Cetartiodactyla | D8: Mysticeti | E8: Balaenopteridae | F8: Balaenoptera | G8: acutorostrata
A9: NC_006926.1 | B9: Balaenoptera bonaerensis | C9: Cetartiodactyla | D9: Mysticeti | E9: Balaenopteridae | F9: Balaenoptera | G9: bonaerensis
A10: NC_006929.1 | B10: Balaenoptera borealis | C10: Cetartiodactyla | D10: Mysticeti | E10: Balaenopteridae | F10: Balaenoptera | G10: borealis
A11: NC_006928.1 | B11: Balaenoptera brydei | C11: Cetartiodactyla | D11: Mysticeti | E11: Balaenopteridae | F11: Balaenoptera | G11: brydei
A12: NC_007938.1 | B12: Balaenoptera edeni | C12: Cetartiodactyla | D12: Mysticeti | E12: Balaenopteridae | F12: Balaenoptera | G12: edeni
A13: NC_001601.1 | B13: Balaenoptera musculus | C13: Cetartiodactyla | D13: Mysticeti | E13: Balaenopteridae | F13: Balaenoptera | G13: musculus
A14: NC_007937.1 | B14: Balaenoptera omurai | C14: Cetartiodactyla | D14: Mysticeti | E14: Balaenopteridae | F14: Balaenoptera | G14: omurai
A15: NC_001321.1 | B15: Balaenoptera physalus | C15: Cetartiodactyla | D15: Mysticeti | E15: Balaenopteridae | F15: Balaenoptera | G15: physalus
... A74: NC_021435.1 | B74: Ziphius cavirostris | C74: Cetartiodactyla | D74: Odontoceti | E74: Ziphiidae | F74: Ziphius | G74: cavirostris
A76: Non-cetacea marine mammals
A77: NC_003314.1 | B77: Dugong dugon | C77: Sirenia | E77: Dugongidae | F77: Dugong | G77: dugon
A78: NC_010302.1 | B78: Trichechus manatus | C78: Sirenia | E78: Trichechidae | F78: Trichechus | G78: manatus
A79: NC_063561.1 | B79: Arctocephalus australis | C79: Carnivora | D79: Caniformia | E79: Otariidae | F79: Arctocephalus | G79: australis
A80: NC_004023.1 | B80: Arctocephalus forsteri | C80: Carnivora | D80: Caniformia | E80: Otariidae | F80: Arctocephalus | G80: forsteri
A81: NC_008417.1 | B81: Arctocephalus pusillus | C81: Carnivora | D81: Caniformia | E81: Otariidae | F81: Arctocephalus | G81: pusillus
A82: NC_008420.1 | B82: Arctocephalus townsendi | C82: Carnivora | D82: Caniformia | E82: Otariidae | F82: Arctocephalus | G82: townsendi
A83: NC_008415.3 | B83: Callorhinus ursinus | C83: Carnivora | D83: Caniformia | E83: Otariidae | F83: Callorhinus | G83: ursinus
A84: NC_004030.2 | B84: Eumetopias jubatus | C84: Carnivora | D84: Caniformia | E84: Otariidae | F84: Eumetopias | G84: jubatus
A85: NC_008419.1 | B85: Neophoca cinerea | C85: Carnivora | D85: Caniformia | E85: Otariidae | F85: Neophoca | G85: cinerea
A86: NC_049152.1 | B86: Otaria byronia | C86: Carnivora | D86: Caniformia | E86: Otariidae | F86: Otaria | G86: byronia
A87: NC_008418.1 | B87: Phocarctos hookeri | C87: Carnivora | D87: Caniformia | E87: Otariidae | F87: Phocarctos | G87: hookeri
A88: NC_008416.1 | B88: Zalophus californianus | C88: Carnivora | D88: Caniformia | E88: Otariidae | F88: Zalophus | G88: californianus
A89: NC_058016.1 | B89: Zalophus japonicus | C89: Carnivora | D89: Caniformia | E89: Otariidae | F89: Zalophus | G89: japonicus
A90: NC_062331.1 | B90: Zalophus wollebaeki | C90: Carnivora | D90: Caniformia | E90: Otariidae | F90: Zalophus | G90: wollebaeki
... A110: NC_079648.1 | B110: Lontra felina | C110: Carnivora | D110: Caniformia | E110: Mustelidae | F110: Lontra | G110: felina
A112: Non-marine mammals
A113: NC_000889.1 | B113: Hippopotamus amphibius | C113: Artiodactyla | E113: Hippopotamidae | F113: Hippopotamus | G113: amphibius
A114: NC_020697.1 | B114: Choeropsis liberiensis | C114: Artiodactyla | E114: Hippopotamidae | F114: Choeropsis | G114: liberiensis
A115: NC_006853.1 | B115: Bos taurus | C115: Artiodactyla | E115: Bovidae | F115: Bos | G115: taurus
A116: NC_000845.1 | B116: Sus scrofa | C116: Artiodactyla | E116: Suidae | F116: Sus | G116: scrofa
A117: NC_005089.1 | B117: Mus musculus | C117: Rodentia | E117: Muridae | F117: Mus | G117: musculus
A118: NC_001700.1 | B118: Felis catus | C118: Carnivora | D118: Feliformia | E118: Felidae | F118: Felis | G118: catus
A119: NC_008092.1 | B119: Canis lupus | C119: Carnivora | D119: Caniformia | E119: Canidae | F119: Canis | G119: lupus
...

Sheet S2 Primers
A1: Table S2. Primer sequences tested in this study
A2: Primer set ID | B2: Region | C2: Reference | D2: Forward primer sequence | E2: Reverse primer sequence | F2: Forward primer length (bp) | G2: Reverse primer length (bp) | H2: Forward primer start position* | I2: Reverse primer start position* | J2: Product length (bp) | K2: Insert length (bp) | L2: GC% (forward) | M2: GC% (reverse)
A3: MiMammal | B3: 12S rRNA | C3: Ushio et al. (2017) | D3: GGGTTGGTAAATTTCGTGCCAGC | E3: CATAGTGGGGTATCTAATCCCAGTTTG | F3: =LEN(D3) -> 23 | G3: =LEN(E3) -> 27 | H3: 297 | I3: 491 | J3: =I3-H3+1+LEN(E3) -> 222 | K3: =J3-F3-G3 -> 172 | L3: 0.52173913 | M3: 0.44444444
A4: MarVer1 | B4: 12S rRNA | C4: Valsecchi et al. (2020) | D4: CGTGCCAGCCACCGCG | E4: GGGTATCTAATCCYAGTTTG | F4: =LEN(D4) -> 16 | G4: =LEN(E4) -> 20 | H4: 311 | I4: 491 | J4: =I4-H4+1+LEN(E4) -> 201 | K4: =J4-F4-G4 -> 165 | L4: 0.8125 | M4: 0.425
A5: MarVer2 | B5: 12S rRNA | C5: Valsecchi et al. (2020) | D5: CCGCCCGTCACYCTC | E5: CTTACCWTGTTACGACTT | F5: =LEN(D5) -> 15 | G5: =LEN(E5) -> 18 | H5: 925 | I5: 1003 | J5: =I5-H5+1+LEN(E5) -> 97 | K5: =J5-F5-G5 -> 64 | L5: 0.76666667 | M5: 0.38888889
A6: MarVer3 | B6: 16S rRNA | C6: Valsecchi et al. (2020) | D6: AGACGAGAAGACCCTRTG | E6: GGATTGCGCTGTTATCCC | F6: =LEN(D6) -> 18 | G6: =LEN(E6) -> 18 | H6: 2170 | I6: 2385 | J6: =I6-H6+1+LEN(E6) -> 234 | K6: =J6-F6-G6 -> 198 | L6: 0.52777778 | M6: 0.55555556
A7: Ceto2 | B7: 16S rRNA | C7: Valsecchi et al. (2020) | D7: CACGCACACACCGCCCG | E7: GTATGCTTACCTTGTTACGAC | F7: =LEN(D7) -> 17 | G7: =LEN(E7) -> 21 | H7: 915 | I7: 1005 | J7: =I7-H7+1+LEN(E7) -> 112 | K7: =J7-F7-G7 -> 74 | L7: 0.76470588 | M7: 0.42857143
A8: Riaz12S | B8: 12S rRNA | C8: Riaz et al. (2011) | D8: TTAGATACCCCACTATGC | E8: TAGAACAGGCTCCTCTAG | F8: =LEN(D8) -> 18 | G8: =LEN(E8) -> 18 | H8: 501 | I8: 618 | J8: =I8-H8+1+LEN(E8) -> 136 | K8: =J8-F8-G8 -> 100 | L8: 0.44444444 | M8: 0.5
A9: Mu31F/Dc320R† (µCeta primer¶) | B9: 12S rRNA | C9: This study | D9: GACACTGAAAATGTCTAGATGG | E9: TYAATCGTATGACCGCGGTG | F9: =LEN(D9) -> 22 | G9: =LEN(E9) -> 20 | H9: 31 | I9: 320 | J9: =I9-H9+1+LEN(E9) -> 310 | K9: =J9-F9-G9 -> 268 | L9: 0.40909091 | M9: 0.525
A10: Mu31F/MiMammalR | B10: 12S rRNA | C10: This study | D10: GACACTGAAAATGTCTAGATGG | E10: CATAGTGGGGTATCTAATCCCAGTTTG | F10: =LEN(D10) -> 22 | G10: =LEN(E10) -> 27 | H10: 31 | I10: 491 | J10: =I10-H10+1+LEN(E10) -> 488 | K10: =J10-F10-G10 -> 439 | L10: 0.40909091 | M10: 0.44444444
A11: Dc321F/Dc495R | B11: 12S rRNA | C11: This study | D11: ACCGCGGTCATACGATTRAC | E11: GCATAGTGGGGTATCTAATCCCAG | F11: =LEN(D11) -> 20 | G11: =LEN(E11) -> 24 | H11: 321 | I11: 495 | J11: =I11-H11+1+LEN(E11) -> 199 | K11: =J11-F11-G11 -> 155 | L11: 0.525 | M11: 0.5
A12: Dc494F- Mu643R | B12: 12S rRNA | C12: This study | D12: ACTGGGATTAGATACCCCACTATGC | E12: GRYTGGTGAGGTTRATCGKGGTTTA | F12: =LEN(D12) -> 25 | G12: =LEN(E12) -> 25 | H12: 494 | I12: 643 | J12: =I12-H12+1+LEN(E12) -> 175 | K12: =J12-F12-G12 -> 125 | L12: 0.48 | M12: 0.48
A13: Mu642F/Dc1015R | B13: 12S rRNA | C13: This study | D13: ATAAACCMCGATYAACCTCACCARYC | E13: CACACYTTCCRGTAYGCTTACC | F13: =LEN(D13) -> 26 | G13: =LEN(E13) -> 22 | H13: 642 | I13: 1015 | J13: =I13-H13+1+LEN(E13) -> 396 | K13: =J13-F13-G13 -> 348 | L13: 0.46153846 | M13: 0.52272727
A14: Mu642F/Mu1021R | B14: 12S rRNA | C14: This study | D14: ATAAACCMCGATYAACCTCACCARYC | E14: CAAGCACACYTTCCRGTAYG | F14: =LEN(D14) -> 26 | G14: =LEN(E14) -> 20 | H14: 642 | I14: 1021 | J14: =I14-H14+1+LEN(E14) -> 400 | K14: =J14-F14-G14 -> 354 | L14: 0.46153846 | M14: 0.525
... A28: Mu9459F/Mu9834R | B28: NAD3 | C28: This study | D28: CTGACTTCCAATCAGTTRGTTTCGG | E28: CATATTYRKCYCATTCYA | F28: =LEN(D28) -> 25 | G28: =LEN(E28) -> 18 | H28: 9459 | I28: 9834 | J28: =I28-H28+1+LEN(E28) -> 394 | K28: =J28-F28-G28 -> 351 | L28: 0.46 | M28: 0.36111111
A29: *Position is based on the mitochondrial genome of Delphinus capensis
A30: †The performance of new primers highlighted in gray were tested empirically
A31: ¶The primer set Mu31F/Dc320R is named µCeta-F/R.

Sheet S3 Queries
A1: Table S3. Queries to downlod vertebrate sequences for in silico PCR
A2: Target taxa | B2: Query | C2: Seqs retrieved | D2: Seqs used | E2: Note
A3: General vertebrates | B3: ("Vertebrata"[Organism] OR "vertebrates"[All Fields]) NOT "Homo sapiens"[Organism] NOT "Canis lupus"[Organism] NOT "Gallus gallus"[Organism] NOT "Bos taurus"[Organism] NOT "Bos grunniens"[Organism] NOT "Equus caballus"[Organism] NOT "Capra hircus"[Organism] NOT "Ovis aries"[Organism] AND (biomol_genomic[PROP] AND ddbj_embl_genbank[filter] AND is_nuccore[filter] AND mitochondrion[filter] AND ("15000"[SLEN] : "30000"[SLEN]) NOT Nuclear[Title]) | C3: 32322 | D3: 32321 | E3: One non-vertebrate species (algae) was manually removed from the retrieved sequences (total sequence used for the analysis was 32,321)
A4: Over-represented taxa
A5: Homo sapiens | B5: "Homo sapiens"[Organism] AND (biomol_genomic[PROP] AND ddbj_embl_genbank[filter] AND is_nuccore[filter] AND mitochondrion[filter] AND ("15000"[SLEN] : "30000"[SLEN]) NOT Nuclear[Title]) | C5: 64361 | D5: 464 | E5: The number of sequences of each over-represented taxon was reduced to about 500 using "seqkit sample" command.
A6: Canis lupus | B6: "Canis lupus"[Organism] AND (biomol_genomic[PROP] AND ddbj_embl_genbank[filter] AND is_nuccore[filter] AND mitochondrion[filter] AND ("15000"[SLEN] : "30000"[SLEN]) NOT Nuclear[Title]) | C6: 4139 | D6: 500 | E6: Same as above
A7: Bos taurus | B7: "Bos taurus"[Organism] AND (biomol_genomic[PROP] AND ddbj_embl_genbank[filter] AND is_nuccore[filter] AND mitochondrion[filter] AND ("15000"[SLEN] : "30000"[SLEN]) NOT Nuclear[Title]) | C7: 1145 | D7: 477 | E7: Same as above
A8: Gallus gallus | B8: "Gallus gallus"[Organism] AND (biomol_genomic[PROP] AND ddbj_embl_genbank[filter] AND is_nuccore[filter] AND mitochondrion[filter] AND ("15000"[SLEN] : "30000"[SLEN]) NOT Nuclear[Title]) | C8: 829 | D8: 492 | E8: Same as above
A9: Bos grunniens | B9: "Bos grunniens"[Organism] AND (biomol_genomic[PROP] AND ddbj_embl_genbank[filter] AND is_nuccore[filter] AND mitochondrion[filter] AND ("15000"[SLEN] : "30000"[SLEN]) NOT Nuclear[Title]) | C9: 617 | D9: 500 | E9: Same as above
A10: Equus caballus | B10: "Equus caballus"[Organism] AND (biomol_genomic[PROP] AND ddbj_embl_genbank[filter] AND is_nuccore[filter] AND mitochondrion[filter] AND ("15000"[SLEN] : "30000"[SLEN]) NOT Nuclear[Title]) | C10: 594 | D10: 500 | E10: Same as above
A11: Capra hircus | B11: "Capra hircus"[Organism] AND (biomol_genomic[PROP] AND ddbj_embl_genbank[filter] AND is_nuccore[filter] AND mitochondrion[filter] AND ("15000"[SLEN] : "30000"[SLEN]) NOT Nuclear[Title]) | C11: 545 | D11: 496 | E11: Same as above
A12: Ovis aries | B12: "Ovis aries"[Organism] AND (biomol_genomic[PROP] AND ddbj_embl_genbank[filter] AND is_nuccore[filter] AND mitochondrion[filter] AND ("15000"[SLEN] : "30000"[SLEN]) NOT Nuclear[Title]) | C12: 503 | D12: 500 | E12: Same as above
A14: Total sequences | C14: =SUM(C3:C12) -> 105055 | D14: =SUM(D3:D12) -> 36250 | E14: Total 36,250 sequences (10,080 species) were used for in silico PCR.

Sheet S4 Pool list
A1: Table S4. List of aquarium dolphin pools for empirical validation of the primer sets
A2: Pool name | B2: Total water volume (m3) | C2: Dolphin species reared | D2: The number of samples collected
A3: First compartment
A4: Main pool | B4: 1200 | C4: Pseudorca crassidens (× 3) Tursiops truncatus (× 2) | D4: 2
A5: North lagoon pool | B5: 500 | C5: Tursiops aduncus (× 1) | D5: 1
A6: South lagoon pool | B6: 500 | C6: Pseudorca crassidens (× 2) Tursiops truncatus (× 3) | D6: 1
A8: Second compartment
A9: Main show pool | B9: 1750 | C9: Pseudorca crassidens (× 2) Tursiops truncatus (× 1) Tursiops aduncus (× 1) | D9: 2
A10: Underwater show pool | B10: 500 | C10: Tursiops aduncus (× 2) Feresa attenuata (× 1) | D10: 1
A11: Medical treatment pool | B11: 500 | C11: Steno bredanensis (× 2) | D11: 1
A12: Reproduction pool | B12: 400 | C12: Pseudorca crassidens (× 2) Tursiops truncatus × aduncus (× 1) | D12: 1

Sheet S5 Primers for Illumina
A1: Table S5. Primer sets for the Illumina library preparation
A2: Method name | D2: Primer sequence | E2: Final amplicon size (bp)
A3: 1st PCR | B3: Primer name | C3: Analyzed samples
A4: Normal 2-step PCR | B4: Mu31F | C4: Aquarium and natural seawater samples | D4: ACACTCTTTCCCTACACGACGCTCTTCCGATCT GACACTGAAAATGTCTAGATGG | E4: 446
A5: Normal 2-step PCR | B5: Dc320R | C5: Aquarium and natural seawater samples | D5: GTGACTGGAGTTCAGACGTGTGCTCTTCCGATCT TYAATCGTATGACCGCGGTG | E5: 446
A6: Normal 2-step PCR | B6: Dc671F | C6: Aquarium and natural seawater samples | D6: ACACTCTTTCCCTACACGACGCTCTTCCGATCT GCTACTYCAGTCTATATACC | E6: 503
A7: Normal 2-step PCR | B7: Dc1015R | C7: Aquarium and natural seawater samples | D7: GTGACTGGAGTTCAGACGTGTGCTCTTCCGATCT CACACYTTCCRGTAYGCTTACC | E7: 503
A8: Normal 2-step PCR | B8: Mu2084F | C8: Aquarium and natural seawater samples | D8: ACACTCTTTCCCTACACGACGCTCTTCCGATCT ATGAAYGGCCACACGAGGGTTTTA | E8: 512
A9: Normal 2-step PCR | B9: Dc2438R | C9: Aquarium and natural seawater samples | D9: GTGACTGGAGTTCAGACGTGTGCTCTTCCGATCT TGTCCTGATCCAACATCGAGG | E9: 512
A10: Normal 2-step PCR | B10: Mu9459F | C10: Aquarium and natural seawater samples | D10: ACACTCTTTCCCTACACGACGCTCTTCCGATCT CTGACTTCCAATCAGTTRGTTTCGG | E10: 519
A11: Normal 2-step PCR | B11: Mu9822R | C11: Aquarium and natural seawater samples | D11: GTGACTGGAGTTCAGACGTGTGCTCTTCCGATCT CATTCTARRCCYTYTTGRG | E11: 519
A13: Early-pooling protocol | B13: Mu31F | C13: Natural positive control samples | D13: ACACTCTTTCCCTACACGACGCTCTTCCGATCT XXXXXXXX GACACTGAAAATGTCTAGATGG | E13: 462
A14: Early-pooling protocol | B14: Dc320R | C14: Natural positive control samples | D14: GTGACTGGAGTTCAGACGTGTGCTCTTCCGATCT XXXXXXXX TYAATCGTATGACCGCGGTG | E14: 462
A16: 2nd PCR
A17: 2nd PCR primer F | C17: All samples | D17: AATGATACGGCGACCACCGAGATCTACAC YYYYYYYY ACACTCTTTCCCTACACGACGCTCTTCCGATCT
A18: 2nd PCR primer R | C18: All samples | D18: CAAGCAGAAGACGGCATACGAGAT YYYYYYYY GTGACTGGAGTTCAGACGTGTGCTCTTCCGATCT
A19: Bold characters indicate primer sequences.
A20: "X" indicates 1st PCR "tagged" sequences to enable early-pooling (i.e., pooling samples after the 1st PCR).
A21: "Y" indicates index sequences appended in the 2nd PCR.
A22: Blue characters indicate the Illumina sequencing primers.
A23: Underlined characters indicate P5/P7 adapter sequences for Illumina sequencing.

Sheet S6 Seq Stat
A1: Table S6. Sequence summary statistics
B2: Sequencing 1 | C2: Sequencing 2 | D2: Sequencing 3
A3: Platform | B3: NovaSeq | C3: iSeq | D3: NovaSeq
A4: Seq mode | B4: 250 PE | C4: 150PE | D4: 250PE
A5: Total reads | B5: =SUM('S7 Track1'!A4, 'S8 Track2'!A4, 'S9 Track3'!A4, 'S10 Track4'!A4) -> 3332370 | C5: ='S11 Track5'!A4+'S12 Track6'!A4 -> 2406398 | D5: ='S13 Track7'!A4 -> 3642219
A6: Overall Q30 | B6: 0.9208 | C6: 0.958 | D6: 0.9253
A8: After DADA2 processing | B8: ='S7 Track1'!G44+ 'S8 Track2'!G48+ 'S9 Track3'!G49+ 'S10 Track4'!G42 -> 2572852 | C8: ='S11 Track5'!G41+'S12 Track6'!G40 -> 2212982 | D8: ='S13 Track7'!G33 -> 3343360
A9: % | B9: =B8/B5 -> 0.77207873 | C9: =C8/C5 -> 0.91962427 | D9: =D8/D5 -> 0.9179459
A11: Samples | B11: Pool + HK water pilot samples | C11: Pool + HK water pilot samples | D11: Natural "positive" samples
A13: Primers | B13: Mu31F/Dc320R | C13: MiMammal | D13: Mu31F/Dc320R
B14: Dc671F/Dc1015R | C14: Ceto2
B15: Mu2084F/Dc2438R
B16: Mu9459F/Mu9822R

Sheet S7 Track1
A1: Table S7. Sequence processing summary for Mu31F/Dc320R
A2: Total sequence reads before processing (Run 1 + 2 + 3)
A3: reads | B3: Q30(%)
A4: =1805816/2 -> 902908 | B4: 93.2
A7: Sequence reads after initial quality filtering and primer trimming
A8: Sequence reads | B8: Run 1 | D8: Run 2 | F8: Run 3 | I8: Total
A9: file | B9: num_seqs | C9: Q30(%) | D9: num_seqs | E9: Q30(%) | F9: num_seqs | G9: Q30(%)
A10: S001 | B10: 48278 | C10: 93.94 | D10: 60723 | E10: 93.38 | F10: 24841 | G10: 93.39 | I10: =SUM(B10,D10,F10) -> 133842
A11: S002 | B11: 49592 | C11: 93.28 | D11: 66459 | E11: 92.74 | F11: 26473 | G11: 93.08 | I11: =SUM(B11,D11,F11) -> 142524
A12: S003 | B12: 40745 | C12: 93.62 | D12: 53694 | E12: 92.96 | F12: 21233 | G12: 93.14 | I12: =SUM(B12,D12,F12) -> 115672
A13: S004 | B13: 43840 | C13: 94.29 | D13: 55019 | E13: 93.49 | F13: 23288 | G13: 93.49 | I13: =SUM(B13,D13,F13) -> 122147
A14: S005 | B14: 46221 | C14: 94.01 | D14: 49093 | E14: 93.24 | F14: 21381 | G14: 93.44 | I14: =SUM(B14,D14,F14) -> 116695
A15: S006 | B15: 47688 | C15: 93.5 | D15: 63605 | E15: 92.95 | F15: 25000 | G15: 93.28 | I15: =SUM(B15,D15,F15) -> 136293
A16: S007 | B16: 47071 | C16: 93.55 | D16: 62370 | E16: 92.83 | F16: 24732 | G16: 92.94 | I16: =SUM(B16,D16,F16) -> 134173
A17: S008 | B17: 252 | C17: 93.72 | D17: 328 | E17: 93.5 | F17: 132 | G17: 94.26 | I17: =SUM(B17,D17,F17) -> 712
A18: S009 | B18: 1 | C18: 98.4 | D18: 0 | E18: NA | F18: 0 | G18: NA | I18: =SUM(B18,D18,F18) -> 1
A19: S010 | B19: 2 | C19: 98.4 | D19: 0 | E19: NA | F19: 1 | G19: 32 | I19: =SUM(B19,D19,F19) -> 3
A20: S011 | B20: 1 | C20: 98.8 | D20: 0 | E20: NA | F20: 0 | G20: NA | I20: =SUM(B20,D20,F20) -> 1
A21: S012 | B21: 2 | C21: 70.6 | D21: 0 | E21: NA | F21: 2 | G21: 83.6 | I21: =SUM(B21,D21,F21) -> 4
A22: S013 | B22: 2 | C22: 96.6 | D22: 0 | E22: NA | F22: 0 | G22: NA | I22: =SUM(B22,D22,F22) -> 2
A23: S014 | B23: 296 | C23: 92.87 | D23: 378 | E23: 93.12 | F23: 148 | G23: 93.25 | I23: =SUM(B23,D23,F23) -> 822
A24: S015 | B24: 0 | C24: NA | D24: 0 | E24: NA | F24: 7 | G24: 62.57 | I24: =SUM(B24,D24,F24) -> 7
A25: S016 | B25: 4 | C25: 85.4 | D25: 5 | E25: 93.04 | F25: 1 | G25: 91.2 | I25: =SUM(B25,D25,F25) -> 10
A27: Total | I27: =SUM(I10:I17) -> 902058
A30: Sequence reads after DADA2 processing
A31: DADA2 tracking
B32: input | C32: filtered | D32: denoised | E32: merged | F32: tabled | G32: nonchim | H32: prop.last.first.
A33: S001 | B33: 133061 | C33: 124759 | D33: 124563 | E33: 122664 | F33: 122664 | G33: 63137 | H33: =G33/B33 -> 0.47449666
A34: S002 | B34: 141698 | C34: 131863 | D34: 131746 | E34: 130839 | F34: 130839 | G34: 122321 | H34: =G34/B34 -> 0.86325142
A35: S003 | B35: 114872 | C35: 107192 | D35: 107113 | E35: 106255 | F35: 106255 | G35: 63521 | H35: =G35/B35 -> 0.552972
A36: S004 | B36: 121444 | C36: 114090 | D36: 113989 | E36: 112749 | F36: 112749 | G36: 76725 | H36: =G36/B36 -> 0.63177267
A37: S005 | B37: 115945 | C37: 108286 | D37: 108140 | E37: 106782 | F37: 106782 | G37: 83059 | H37: =G37/B37 -> 0.71636552
A38: S006 | B38: 135499 | C38: 126701 | D38: 126462 | E38: 124402 | F38: 124402 | G38: 98223 | H38: =G38/B38 -> 0.72489834
A39: S007 | B39: 133376 | C39: 124173 | D39: 124016 | E39: 123021 | F39: 123021 | G39: 120475 | H39: =G39/B39 -> 0.90327345
A40: S008 | B40: 708 | C40: 670 | D40: 670 | E40: 666 | F40: 666 | G40: 617 | H40: =G40/B40 -> 0.87146893
A41: S013 | B41: 2 | C41: 2 | D41: 2 | E41: 2 | F41: 2 | G41: 2 | H41: =G41/B41 -> 1
A42: S014 | B42: 814 | C42: 756 | D42: 756 | E42: 756 | F42: 756 | G42: 756 | H42: =G42/B42 -> 0.92874693
A44: Total | B44: =SUM(B33:B42) -> 897419 | C44: =SUM(C33:C42) -> 838492 | D44: =SUM(D33:D42) -> 837457 | E44: =SUM(E33:E42) -> 828136 | F44: =SUM(F33:F42) -> 828136 | G44: =SUM(G33:G42) -> 628836 | H44: =G44/B44 -> 0.70071616

Sheet S8 Track2
A1: Table S8. Sequence processing summary for Dc671F/Dc1015R
A2: Total sequence reads before processing (Run 1 + 2 + 3)
A3: reads | B3: Q30(%)
A4: =1562010/2 -> 781005 | B4: 92.39
A7: Sequence reads after initial quality filtering and primer trimming
A8: Sequence reads | B8: Run 1 | D8: Run 2 | F8: Run 3 | I8: Total
A9: file | B9: num_seqs | C9: Q30(%) | D9: num_seqs | E9: Q30(%) | F9: num_seqs | G9: Q30(%)
A10: S017 | B10: 37230 | C10: 93.15 | D10: 47941 | E10: 92.28 | F10: 20305 | G10: 92.55 | I10: =SUM(B10,D10,F10) -> 105476
A11: S018 | B11: 39862 | C11: 93.27 | D11: 54918 | E11: 92.26 | F11: 22242 | G11: 92.77 | I11: =SUM(B11,D11,F11) -> 117022
A12: S019 | B12: 40191 | C12: 93.25 | D12: 54100 | E12: 92.39 | F12: 22052 | G12: 92.63 | I12: =SUM(B12,D12,F12) -> 116343
A13: S020 | B13: 34980 | C13: 93.23 | D13: 45354 | E13: 92.22 | F13: 20280 | G13: 92.49 | I13: =SUM(B13,D13,F13) -> 100614
A14: S021 | B14: 36982 | C14: 93.14 | D14: 47477 | E14: 92.07 | F14: 20307 | G14: 92.48 | I14: =SUM(B14,D14,F14) -> 104766
A15: S022 | B15: 39683 | C15: 93.24 | D15: 52474 | E15: 92.33 | F15: 21633 | G15: 92.66 | I15: =SUM(B15,D15,F15) -> 113790
A16: S023 | B16: 38755 | C16: 92.98 | D16: 51387 | E16: 91.87 | F16: 21643 | G16: 92.32 | I16: =SUM(B16,D16,F16) -> 111785
A17: S024 | B17: 103 | C17: 95.08 | D17: 145 | E17: 90.67 | F17: 56 | G17: 91.52 | I17: =SUM(B17,D17,F17) -> 304
A18: S025 | B18: 2 | C18: 96.2 | D18: 0 | E18: NA | F18: 0 | G18: NA | I18: =SUM(B18,D18,F18) -> 2
A19: S026 | B19: 2 | C19: 95.4 | D19: 0 | E19: NA | F19: 1 | G19: 49.6 | I19: =SUM(B19,D19,F19) -> 3
A20: S027 | B20: 1 | C20: 94.8 | D20: 0 | E20: NA | F20: 0 | G20: NA | I20: =SUM(B20,D20,F20) -> 1
A21: S028 | B21: 4 | C21: 93.2 | D21: 0 | E21: NA | F21: 0 | G21: NA | I21: =SUM(B21,D21,F21) -> 4
A22: S029 | B22: 0 | C22: NA | D22: 0 | E22: NA | F22: 0 | G22: NA | I22: =SUM(B22,D22,F22) -> 0
A23: S030 | B23: 3737 | C23: 93.62 | D23: 5099 | E23: 92.61 | F23: 2058 | G23: 92.96 | I23: =SUM(B23,D23,F23) -> 10894
A24: S031 | B24: 0 | C24: NA | D24: 1 | E24: 96 | F24: 0 | G24: NA | I24: =SUM(B24,D24,F24) -> 1
A25: S032 | B25: 0 | C25: NA | D25: 0 | E25: NA | F25: 0 | G25: NA | I25: =SUM(B25,D25,F25) -> 0
A27: Total | I27: =SUM(I10:I17) -> 770100
A30: Sequence reads after DADA2 processing
A31: DADA2 tracking
B32: input | C32: filtered | D32: denoised | E32: merged | F32: tabled | G32: nonchim | H32: prop.last.first.
A33: S017 | B33: 104850 | C33: 98279 | D33: 98231 | E33: 97723 | F33: 97723 | G33: 77531 | H33: =G33/B33 -> 0.73944683
A34: S018 | B34: 116208 | C34: 108788 | D34: 108700 | E34: 108454 | F34: 108454 | G34: 106727 | H34: =G34/B34 -> 0.91841353
A35: S019 | B35: 115520 | C35: 108005 | D35: 107913 | E35: 107255 | F35: 107255 | G35: 88643 | H35: =G35/B35 -> 0.76733899
A36: S020 | B36: 99986 | C36: 93928 | D36: 93897 | E36: 93376 | F36: 93376 | G36: 77508 | H36: =G36/B36 -> 0.77518853
A37: S021 | B37: 103484 | C37: 96880 | D37: 96855 | E37: 96270 | F37: 96270 | G37: 82566 | H37: =G37/B37 -> 0.79786247
A38: S022 | B38: 113091 | C38: 106040 | D38: 105853 | E38: 104649 | F38: 104649 | G38: 80804 | H38: =G38/B38 -> 0.71450425
A39: S023 | B39: 111103 | C39: 103938 | D39: 103921 | E39: 103626 | F39: 103626 | G39: 100330 | H39: =G39/B39 -> 0.90303592
A40: S024 | B40: 302 | C40: 284 | D40: 284 | E40: 283 | F40: 283 | G40: 272 | H40: =G40/B40 -> 0.90066225
A41: S025 | B41: 1 | C41: 1 | D41: 1 | E41: 1 | F41: 1 | G41: 1 | H41: =G41/B41 -> 1
A42: S026 | B42: 2 | C42: 2 | D42: 2 | E42: 2 | F42: 2 | G42: 2 | H42: =G42/B42 -> 1
A43: S027 | B43: 1 | C43: 1 | D43: 1 | E43: 1 | F43: 1 | G43: 1 | H43: =G43/B43 -> 1
A44: S028 | B44: 4 | C44: 4 | D44: 4 | E44: 4 | F44: 4 | G44: 4 | H44: =G44/B44 -> 1
... A46: S031 | B46: 1 | C46: 1 | D46: 1 | E46: 1 | F46: 1 | G46: 1 | H46: =G46/B46 -> 1
...

Sheet S9 Track3
A1: Table S9. Sequence processing summary for Mu2084F/Dc2438R
A2: Total sequence reads before processing (Run 1 + 2 + 3)
A3: reads | B3: Q30(%)
A4: 782716 | B4: 91.69
A7: Sequence reads after initial quality filtering and primer trimming
A8: Sequence reads | B8: Run 1 | D8: Run 2 | F8: Run 3 | I8: Total
A9: file | B9: num_seqs | C9: Q30(%) | D9: num_seqs | E9: Q30(%) | F9: num_seqs | G9: Q30(%)
A10: S033 | B10: 26784 | C10: 92.71 | D10: 37861 | E10: 92.15 | F10: 14614 | G10: 92.32 | I10: =SUM(B10,D10,F10) -> 79259
A11: S034 | B11: 27172 | C11: 92.47 | D11: 38167 | E11: 91.88 | F11: 14900 | G11: 92.2 | I11: =SUM(B11,D11,F11) -> 80239
A12: S035 | B12: 27731 | C12: 92.61 | D12: 38004 | E12: 91.95 | F12: 14642 | G12: 92.15 | I12: =SUM(B12,D12,F12) -> 80377
A13: S036 | B13: 25360 | C13: 92.94 | D13: 36393 | E13: 92.38 | F13: 14718 | G13: 92.15 | I13: =SUM(B13,D13,F13) -> 76471
A14: S037 | B14: 26951 | C14: 92.81 | D14: 37843 | E14: 92.06 | F14: 14630 | G14: 92.29 | I14: =SUM(B14,D14,F14) -> 79424
A15: S038 | B15: 25753 | C15: 92.62 | D15: 35848 | E15: 91.97 | F15: 14126 | G15: 92.09 | I15: =SUM(B15,D15,F15) -> 75727
A16: S039 | B16: 26696 | C16: 92.93 | D16: 37832 | E16: 92.28 | F16: 14613 | G16: 92.5 | I16: =SUM(B16,D16,F16) -> 79141
A17: S040 | B17: 169 | C17: 91.74 | D17: 214 | E17: 92.68 | F17: 78 | G17: 93.27 | I17: =SUM(B17,D17,F17) -> 461
A18: S041 | B18: 34 | C18: 92.39 | D18: 33 | E18: 92.41 | F18: 11 | G18: 93.49 | I18: =SUM(B18,D18,F18) -> 78
A19: S042 | B19: 39600 | C19: 92.47 | D19: 55796 | E19: 91.83 | F19: 21908 | G19: 92.17 | I19: =SUM(B19,D19,F19) -> 117304
A20: S043 | B20: 101 | C20: 92.71 | D20: 90 | E20: 94.59 | F20: 34 | G20: 93.22 | I20: =SUM(B20,D20,F20) -> 225
A21: S044 | B21: 20 | C21: 87.46 | D21: 0 | E21: NA | F21: 1 | G21: 81.6 | I21: =SUM(B21,D21,F21) -> 21
A22: S045 | B22: 896 | C22: 94.07 | D22: 1228 | E22: 93.26 | F22: 526 | G22: 93.17 | I22: =SUM(B22,D22,F22) -> 2650
A23: S046 | B23: 37722 | C23: 93.09 | D23: 52329 | E23: 92.38 | F23: 21282 | G23: 92.71 | I23: =SUM(B23,D23,F23) -> 111333
A24: S047 | B24: 3 | C24: 96.67 | D24: 2 | E24: 97.4 | F24: 1 | G24: 94.4 | I24: =SUM(B24,D24,F24) -> 6
A25: S048 | B25: 0 | C25: NA | D25: 0 | E25: NA | F25: 0 | G25: NA | I25: =SUM(B25,D25,F25) -> 0
A27: Total | I27: =SUM(I10:I17) -> 551099
A30: Sequence reads after DADA2 processing
A31: DADA2 tracking
B32: input | C32: filtered | D32: denoised | E32: merged | F32: tabled | G32: nonchim | H32: prop.last.first.
A33: S033 | B33: 78819 | C33: 73104 | D33: 73068 | E33: 72776 | F33: 72776 | G33: 52597 | H33: =G33/B33 -> 0.66731372
A34: S034 | B34: 79708 | C34: 73587 | D34: 73553 | E34: 73306 | F34: 73306 | G34: 69981 | H34: =G34/B34 -> 0.87796708
A35: S035 | B35: 79896 | C35: 73669 | D35: 73628 | E35: 73395 | F35: 73395 | G35: 56826 | H35: =G35/B35 -> 0.71124962
A36: S036 | B36: 76058 | C36: 70874 | D36: 70817 | E36: 70516 | F36: 70516 | G36: 60671 | H36: =G36/B36 -> 0.79769387
A37: S037 | B37: 78996 | C37: 73181 | D37: 73154 | E37: 72904 | F37: 72904 | G37: 62657 | H37: =G37/B37 -> 0.79316674
A38: S038 | B38: 75301 | C38: 69681 | D38: 69571 | E38: 68478 | F38: 68478 | G38: 42176 | H38: =G38/B38 -> 0.5600988
A39: S039 | B39: 78000 | C39: 72352 | D39: 72214 | E39: 71131 | F39: 71131 | G39: 68266 | H39: =G39/B39 -> 0.87520513
A40: S040 | B40: 454 | C40: 422 | D40: 422 | E40: 422 | F40: 422 | G40: 416 | H40: =G40/B40 -> 0.91629956
A41: S041 | B41: 78 | C41: 70 | D41: 70 | E41: 70 | F41: 70 | G41: 70 | H41: =G41/B41 -> 0.8974359
A42: S042 | B42: 116006 | C42: 106496 | D42: 106489 | E42: 106487 | F42: 106487 | G42: 106447 | H42: =G42/B42 -> 0.91759909
A43: S043 | B43: 221 | C43: 209 | D43: 209 | E43: 209 | F43: 209 | G43: 209 | H43: =G43/B43 -> 0.94570136
A44: S044 | B44: 19 | C44: 16 | D44: 16 | E44: 16 | F44: 16 | G44: 16 | H44: =G44/B44 -> 0.84210526
... A47: S047 | B47: 5 | C47: 5 | D47: 5 | E47: 5 | F47: 5 | G47: 5 | H47: =G47/B47 -> 1
...

Sheet S10 Track4
A1: Table S10. Sequence processing summary for Mu9459F/Mu9822R
A2: Total sequence reads before processing (Run 1 + 2 + 3)
A3: reads | B3: Q30(%)
A4: =1731482/2 -> 865741 | B4: 91
A7: Sequence reads after initial quality filtering and primer trimming
A8: Sequence reads | B8: Run 1 | D8: Run 2 | F8: Run 3 | I8: Total
A9: file | B9: num_seqs | C9: Q30(%) | D9: num_seqs | E9: Q30(%) | F9: num_seqs | G9: Q30(%)
A10: S049 | B10: 42687 | C10: 90.9 | D10: 56893 | E10: 90.54 | F10: 23754 | G10: 91.33 | I10: =SUM(B10,D10,F10) -> 123334
A11: S050 | B11: 46705 | C11: 91.12 | D11: 62550 | E11: 90.69 | F11: 25654 | G11: 91.26 | I11: =SUM(B11,D11,F11) -> 134909
A12: S051 | B12: 43236 | C12: 90.58 | D12: 58521 | E12: 90.35 | F12: 24200 | G12: 91.01 | I12: =SUM(B12,D12,F12) -> 125957
A13: S052 | B13: 38806 | C13: 91.03 | D13: 52041 | E13: 90.72 | F13: 21962 | G13: 91.18 | I13: =SUM(B13,D13,F13) -> 112809
A14: S053 | B14: 40569 | C14: 91.02 | D14: 53901 | E14: 90.56 | F14: 22355 | G14: 91.38 | I14: =SUM(B14,D14,F14) -> 116825
A15: S054 | B15: 41256 | C15: 91.15 | D15: 55526 | E15: 90.82 | F15: 23230 | G15: 91.39 | I15: =SUM(B15,D15,F15) -> 120012
A16: S055 | B16: 45561 | C16: 90.51 | D16: 61197 | E16: 90.01 | F16: 25046 | G16: 90.78 | I16: =SUM(B16,D16,F16) -> 131804
A17: S056 | B17: 30 | C17: 90.99 | D17: 32 | E17: 91.13 | F17: 14 | G17: 89.6 | I17: =SUM(B17,D17,F17) -> 76
A18: S057 | B18: 0 | C18: NA | D18: 0 | E18: NA | F18: 0 | G18: NA | I18: =SUM(B18,D18,F18) -> 0
A19: S058 | B19: 0 | C19: NA | D19: 0 | E19: NA | F19: 11 | G19: 83.16 | I19: =SUM(B19,D19,F19) -> 11
A20: S059 | B20: 0 | C20: NA | D20: 0 | E20: NA | F20: 0 | G20: NA | I20: =SUM(B20,D20,F20) -> 0
A21: S060 | B21: 0 | C21: NA | D21: 0 | E21: NA | F21: 1 | G21: 79.2 | I21: =SUM(B21,D21,F21) -> 1
A22: S061 | B22: 0 | C22: NA | D22: 0 | E22: NA | F22: 0 | G22: NA | I22: =SUM(B22,D22,F22) -> 0
A23: S062 | B23: 0 | C23: NA | D23: 0 | E23: NA | F23: 2 | G23: 69.6 | I23: =SUM(B23,D23,F23) -> 2
A24: S063 | B24: 0 | C24: NA | D24: 0 | E24: NA | F24: 1 | G24: 80.8 | I24: =SUM(B24,D24,F24) -> 1
A25: S064 | B25: 0 | C25: NA | D25: 0 | E25: NA | F25: 0 | G25: NA | I25: =SUM(B25,D25,F25) -> 0
A27: Total | I27: =SUM(I10:I17) -> 865726
A30: Sequence reads after DADA2 processing
A31: DADA2 tracking
B32: input | C32: filtered | D32: denoised | E32: merged | F32: tabled | G32: nonchim | H32: prop.last.first.
A33: S049 | B33: 122330 | C33: 112567 | D33: 112435 | E33: 112185 | F33: 112185 | G33: 88810 | H33: =G33/B33 -> 0.72598708
A34: S050 | B34: 133719 | C34: 122539 | D34: 122393 | E34: 121724 | F34: 121724 | G34: 114942 | H34: =G34/B34 -> 0.85957867
A35: S051 | B35: 124696 | C35: 113879 | D35: 113769 | E35: 113550 | F35: 113550 | G35: 93461 | H35: =G35/B35 -> 0.74951081
A36: S052 | B36: 111760 | C36: 103190 | D36: 103082 | E36: 102779 | F36: 102779 | G36: 81194 | H36: =G36/B36 -> 0.72650322
A37: S053 | B37: 115662 | C37: 106285 | D37: 106215 | E37: 105833 | F37: 105833 | G37: 97547 | H37: =G37/B37 -> 0.84337985
A38: S054 | B38: 118873 | C38: 109137 | D38: 109009 | E38: 108144 | F38: 108144 | G38: 102147 | H38: =G38/B38 -> 0.85929521
A39: S055 | B39: 130689 | C39: 119664 | D39: 119597 | E39: 119001 | F39: 119001 | G39: 117057 | H39: =G39/B39 -> 0.8956913
A40: S056 | B40: 75 | C40: 70 | D40: 70 | E40: 69 | F40: 69 | G40: 67 | H40: =G40/B40 -> 0.89333333
A42: Total | B42: =SUM(B33:B40) -> 857804 | C42: =SUM(C33:C40) -> 787331 | D42: =SUM(D33:D40) -> 786570 | E42: =SUM(E33:E40) -> 783285 | F42: =SUM(F33:F40) -> 783285 | G42: =SUM(G33:G40) -> 695225 | H42: =G42/B42 -> 0.81047069

Sheet S11 Track5
A1: Table S11. Sequence processing summary for MiMammal
A2: Total sequence reads before processing
A3: reads | B3: Q30(%)
A4: =2157512/2 -> 1078756 | B4: 96.72
A7: Sequence reads after initial quality filtering and primer trimming
A8: Sequence reads | B8: Run 1
A9: file | B9: num_seqs | C9: Q30(%)
A10: R001 | B10: 95085 | C10: 96.91
A11: R002 | B11: 92090 | C11: 97.01
A12: R003 | B12: 91617 | C12: 96.95
A13: R004 | B13: 89657 | C13: 96.95
A14: R005 | B14: 86643 | C14: 97.26
A15: R006 | B15: 95378 | C15: 96.72
A16: R007 | B16: 103963 | C16: 96.87
A17: R008 | B17: 147928 | C17: 96.8
A18: R009 | B18: 135721 | C18: 94.89
A19: R010 | B19: 140664 | C19: 96.86
A20: R011 | B20: 0 | C20: 0
A21: R012 | B21: 10 | C21: 98.08
A23: Total | B23: =SUM(B10:B21) -> 1078756
A26: Sequence reads after DADA2 processing
A27: DADA2 tracking
B28: input | C28: filtered | D28: denoised | E28: merged | F28: tabled | G28: nonchim | H28: prop.last.first.
A29: R001 | B29: 93542 | C29: 91825 | D29: 91780 | E29: 90530 | F29: 90530 | G29: 82593 | H29: =G29/B29 -> 0.88295097
A30: R002 | B30: 90665 | C30: 88963 | D30: 88958 | E30: 88155 | F30: 88155 | G30: 85113 | H30: =G30/B30 -> 0.93876358
A31: R003 | B31: 90010 | C31: 88172 | D31: 88155 | E31: 87056 | F31: 87056 | G31: 77730 | H31: =G31/B31 -> 0.86357071
A32: R004 | B32: 88340 | C32: 86745 | D32: 86711 | E32: 85880 | F32: 85880 | G32: 82334 | H32: =G32/B32 -> 0.93201268
A33: R005 | B33: 85666 | C33: 84417 | D33: 84381 | E33: 83979 | F33: 83979 | G33: 81757 | H33: =G33/B33 -> 0.95436929
A34: R006 | B34: 93492 | C34: 91777 | D34: 91755 | E34: 90611 | F34: 90611 | G34: 72642 | H34: =G34/B34 -> 0.77698627
A35: R007 | B35: 102365 | C35: 100480 | D35: 100461 | E35: 99744 | F35: 99744 | G35: 99277 | H35: =G35/B35 -> 0.96983344
A36: R008 | B36: 146460 | C36: 143967 | D36: 143962 | E36: 143942 | F36: 143942 | G36: 143942 | H36: =G36/B36 -> 0.98280759
A37: R009 | B37: 133987 | C37: 127050 | D37: 127037 | E37: 125509 | F37: 125509 | G37: 125508 | H37: =G37/B37 -> 0.93671774
A38: R010 | B38: 139341 | C38: 137038 | D38: 137032 | E38: 137016 | F38: 137016 | G38: 136965 | H38: =G38/B38 -> 0.98294831
A39: R012 | B39: 10 | C39: 10 | D39: 10 | E39: 10 | F39: 10 | G39: 10 | H39: =G39/B39 -> 1
A41: Total | B41: =SUM(B29:B39) -> 1063878 | C41: =SUM(C29:C39) -> 1040444 | D41: =SUM(D29:D39) -> 1040242 | E41: =SUM(E29:E39) -> 1032432 | F41: =SUM(F29:F39) -> 1032432 | G41: =SUM(G29:G39) -> 987871 | H41: =G41/B41 -> 0.92855666

Sheet S12 Track6
A1: Table S12. Sequence processing summary for Ceto2
A2: Total sequence reads before processing
A3: reads | B3: Q30(%)
A4: =2655284/2 -> 1327642 | B4: 95.06
A7: Sequence reads after initial quality filtering and primer trimming
A8: Sequence reads | B8: Run 1
A9: file | B9: num_seqs | C9: Q30(%)
A10: R013 | B10: 150660 | C10: 94.38
A11: R014 | B11: 141305 | C11: 95.05
A12: R015 | B12: 178749 | C12: 94.55
A13: R016 | B13: 163730 | C13: 94.28
A14: R017 | B14: 151254 | C14: 94.44
A15: R018 | B15: 142963 | C15: 94.8
A16: R019 | B16: 135156 | C16: 94.38
A17: R020 | B17: 69258 | C17: 94.46
A18: R021 | B18: 88735 | C18: 94.45
A19: R022 | B19: 105744 | C19: 93.6
A20: R023 | B20: 0 | C20: NA
A21: R024 | B21: 88 | C21: 96.15
A23: Total | B23: =SUM(B10:B21) -> 1327642 | C23: 95.06
A26: DADA2 tracking
B27: input | C27: filtered | D27: denoised | E27: merged | F27: tabled | G27: nonchim | H27: prop.last.first.
A28: R013 | B28: 148038 | C28: 147714 | D28: 147675 | E28: 146044 | F28: 146044 | G28: 136056 | H28: =G28/B28 -> 0.91906132
A29: R014 | B29: 139023 | C29: 138779 | D29: 138709 | E29: 137709 | F29: 137709 | G29: 135185 | H29: =G29/B29 -> 0.97239306
A30: R015 | B30: 175464 | C30: 175121 | D30: 175091 | E30: 173253 | F30: 173253 | G30: 162119 | H30: =G30/B30 -> 0.92394451
A31: R016 | B31: 160892 | C31: 160556 | D31: 160459 | E31: 158952 | F31: 158952 | G31: 150381 | H31: =G31/B31 -> 0.93467046
A32: R017 | B32: 149033 | C32: 148683 | D32: 148594 | E32: 147632 | F32: 147632 | G32: 141934 | H32: =G32/B32 -> 0.95236625
A33: R018 | B33: 140289 | C33: 140040 | D33: 139955 | E33: 137886 | F33: 137886 | G33: 136159 | H33: =G33/B33 -> 0.97056077
A34: R019 | B34: 132682 | C34: 132472 | D34: 132295 | E34: 129993 | F34: 129993 | G34: 125403 | H34: =G34/B34 -> 0.94513951
A35: R020 | B35: 68008 | C35: 67896 | D35: 67804 | E35: 65019 | F35: 65019 | G35: 62500 | H35: =G35/B35 -> 0.91900953
A36: R021 | B36: 87260 | C36: 87127 | D36: 86980 | E36: 84950 | F36: 84950 | G36: 82360 | H36: =G36/B36 -> 0.94384598
A37: R022 | B37: 104069 | C37: 103875 | D37: 103637 | E37: 99811 | F37: 99811 | G37: 92927 | H37: =G37/B37 -> 0.89293642
A38: R024 | B38: 87 | C38: 87 | D38: 87 | E38: 87 | F38: 87 | G38: 87 | H38: =G38/B38 -> 1
A40: Total | B40: =SUM(B28:B38) -> 1304845 | C40: =SUM(C28:C38) -> 1302350 | D40: =SUM(D28:D38) -> 1301286 | E40: =SUM(E28:E38) -> 1281336 | F40: =SUM(F28:F38) -> 1281336 | G40: =SUM(G28:G38) -> 1225111 | H40: =G40/B40 -> 0.93889389

Sheet S13 Track7
A1: Table S13. Sequence processing summary for field positive samples
A2: Total sequence reads before processing
A3: reads | B3: Q30(%)
A4: =7284438/2 -> 3642219 | B4: 92.53
A7: Sequence reads after initial quality filtering and primer trimming
A8: Sequence reads | B8: Run 1 | D8: Run 2 | F8: Run 3 | I8: Total
A9: file | B9: num_seqs | C9: Q30(%) | D9: num_seqs | E9: Q30(%) | F9: num_seqs | G9: Q30(%)
A10: T001 | B10: 1255747 | C10: 90.62 | D10: 452308 | E10: 92.38 | F10: 258572 | G10: 92.89 | I10: =SUM(B10, D10, F10) -> 1966627
A11: T002 | B11: 929930 | C11: 90.78 | D11: 423971 | E11: 92.61 | F11: 218625 | G11: 92.95 | I11: =SUM(B11, D11, F11) -> 1572526
A12: T003 | B12: 0 | C12: 0 | D12: 0 | E12: 0 | F12: 0 | G12: 0 | I12: =SUM(B12, D12, F12) -> 0
A13: T004 | B13: 45 | C13: 87.21 | D13: 47 | E13: 87 | F13: 31 | G13: 82.07 | I13: =SUM(B13, D13, F13) -> 123
A14: T005 | B14: 59087 | C14: 92.73 | D14: 29195 | E14: 94.17 | F14: 14656 | G14: 94.32 | I14: =SUM(B14, D14, F14) -> 102938
A15: T006 | B15: 0 | C15: 0 | D15: 0 | E15: 0 | F15: 0 | G15: 0 | I15: =SUM(B15, D15, F15) -> 0
A16: T007 | B16: 0 | C16: 0 | D16: 0 | E16: 0 | F16: 1 | G16: 86.78 | I16: =SUM(B16, D16, F16) -> 1
A17: T008 | B17: 3 | C17: 72.31 | D17: 0 | E17: 0 | F17: 1 | G17: 88.02 | I17: =SUM(B17, D17, F17) -> 4
A19: Total | I19: =SUM(I10:I17) -> 3642219
A22: DADA2 tracking
B23: input | C23: filtered | D23: denoised | E23: merged | F23: tabled | G23: nonchim | H23: prop.last.first.
A24: T001 | B24: 1960321 | C24: 1823107 | D24: 1823005 | E24: 1801076 | F24: 1801076 | G24: 1800670 | H24: =G24/B24 -> 0.91855875
A25: T002 | B25: 1567847 | C25: 1465421 | D25: 1465307 | E25: 1447675 | F25: 1447675 | G25: 1447562 | H25: =G25/B25 -> 0.92328014
A26: T003 | B26: 0 | C26: 0 | D26: 0 | E26: 0 | F26: 0 | G26: 0 | H26: NA
A27: T004 | B27: 1 | C27: 1 | D27: 1 | E27: 1 | F27: 1 | G27: 1 | H27: =G27/B27 -> 1
A28: T005 | B28: 102517 | C28: 96243 | D28: 96233 | E28: 95129 | F28: 95129 | G28: 95126 | H28: =G28/B28 -> 0.92790464
A29: T006 | B29: 0 | C29: 0 | D29: 0 | E29: 0 | F29: 0 | G29: 0 | H29: NA
A30: T007 | B30: 1 | C30: 1 | D30: 1 | E30: 1 | F30: 1 | G30: 1 | H30: =G30/B30 -> 1
A31: T008 | B31: 0 | C31: 0 | D31: 0 | E31: 0 | F31: 0 | G31: 0 | H31: NA
A33: Total | B33: =SUM(B24:B31) -> 3630687 | C33: =SUM(C24:C31) -> 3384773 | D33: =SUM(D24:D31) -> 3384547 | E33: =SUM(E24:E31) -> 3343882 | F33: =SUM(F24:F31) -> 3343882 | G33: =SUM(G24:G31) -> 3343360 | H33: =G33/B33 -> 0.92086153
A36: OTU assignment | B36: S. chinensis
A37: T001 | B37: 1800670
A38: T002 | B38: 1447562
A39: T003 | B39: 0
A40: T004 | B40: 1
A41: T005 | B41: 95126
A42: T006 | B42: 0
A43: T007 | B43: 1
A44: T008 | B44: 0
A46: Total | B46: =SUM(B37:B44) -> 3343360

Sheet S14 ASV matrix1
G1: Claident automatic taxa assignment
G2: family | H2: Delphinidae | I2: Delphinidae | J2: Delphinidae | K2: Delphinidae | L2: Delphinidae | M2: Delphinidae | N2: Delphinidae | O2: Delphinidae | P2: Delphinidae | Q2: Delphinidae | R2: Delphinidae | S2: Delphinidae | T2: Delphinidae | U2: Delphinidae | V2: Delphinidae | W2: Delphinidae | X2: Phocoenidae | Y2: Delphinidae | Z2: Delphinidae | AA2: Delphinidae | AB2: Delphinidae | AC2: Delphinidae | AD2: Delphinidae | AE2: Delphinidae | AF2: Delphinidae | AG2: Delphinidae | AH2: Delphinidae | AJ2: Delphinidae | AK2: Delphinidae | AL2: Delphinidae | AM2: Delphinidae | AN2: Delphinidae | AO2: Delphinidae | AP2: Delphinidae | AQ2: Delphinidae | AR2: Delphinidae | AS2: Delphinidae | AT2: Delphinidae | AU2: Delphinidae | AV2: Delphinidae | AW2: Delphinidae | AX2: Delphinidae | AY2: Delphinidae | BA2: Delphinidae | BC2: Delphinidae | BD2: Delphinidae | BE2: Delphinidae | BF2: Delphinidae | BG2: Delphinidae | BH2: Delphinidae | BI2: Delphinidae | BJ2: Delphinidae | BK2: Delphinidae | BL2: Delphinidae | BO2: Delphinidae | BP2: Delphinidae | BQ2: Delphinidae | BR2: Delphinidae | BS2: Delphinidae | BT2: Delphinidae | BU2: Delphinidae | BV2: Delphinidae | BW2: Delphinidae | BX2: Delphinidae | BY2: Delphinidae | BZ2: Delphinidae | CA2: Delphinidae | CB2: Delphinidae | CC2: Delphinidae | CE2: Delphinidae | CF2: Delphinidae | CG2: Delphinidae | CH2: Delphinidae | CI2: Delphinidae | CJ2: Delphinidae | CM2: Delphinidae | CN2: Delphinidae | CO2: Delphinidae | CP2: Delphinidae | CQ2: Delphinidae | CR2: Delphinidae | CS2: Delphinidae | CT2: Delphinidae | CU2: Delphinidae | CV2: Delphinidae | CW2: Delphinidae | CY2: Delphinidae | DA2: Delphinidae | DB2: Delphinidae | DC2: Delphinidae | DD2: Delphinidae | DE2: Delphinidae | DF2: Delphinidae | DG2: Delphinidae | DH2: Delphinidae | DI2: Delphinidae | DK2: Delphinidae | DL2: Delphinidae | DN2: Delphinidae | DO2: Delphinidae | DQ2: Delphinidae | DR2: Delphinidae | DS2: Delphinidae | DT2: Delphinidae | DU2: Delphinidae | DV2: Delphinidae | DW2: Delphinidae | DX2: Delphinidae | DY2: Delphinidae | DZ2: Delphinidae | EC2: Delphinidae | ED2: Delphinidae | EF2: Delphinidae | EH2: Delphinidae | EJ2: Delphinidae | EM2: Delphinidae | EP2: Delphinidae | EQ2: Delphinidae | ER2: Hominidae | ES2: Delphinidae | ET2: Delphinidae | EU2: Delphinidae | EV2: Delphinidae
G3: species | H3: Tursiops aduncus | I3: Pseudorca crassidens | J3: Stenella longirostris | K3: Tursiops truncatus | L3: Tursiops truncatus | M3: Tursiops truncatus | O3: Peponocephala electra | Q3: Tursiops aduncus | T3: Tursiops aduncus | U3: Tursiops aduncus | Y3: Tursiops truncatus | Z3: Stenella longirostris | AC3: Tursiops aduncus | AE3: Stenella longirostris | AF3: Stenella longirostris | AK3: Tursiops truncatus | AM3: Stenella longirostris | AO3: Tursiops aduncus | AP3: Tursiops truncatus | AQ3: Stenella longirostris | AS3: Tursiops truncatus | AU3: Stenella longirostris | AX3: Tursiops truncatus | AY3: Stenella longirostris | BH3: Stenella longirostris | BK3: Tursiops truncatus | BP3: Tursiops truncatus | BQ3: Stenella longirostris | BV3: Stenella longirostris | BX3: Tursiops australis | CG3: Tursiops truncatus | CQ3: Tursiops aduncus | CW3: Stenella longirostris | DE3: Tursiops truncatus | DI3: Stenella longirostris | DR3: Tursiops truncatus | DU3: Peponocephala electra | DZ3: Tursiops truncatus | EH3: Pseudorca crassidens
